Workbook

Sheet G3 Multi 
A1: TIPO | B1: CODIGO | C1: PRODUCTO | D1: PRECIO $ Publicado | E1: PRECIO $ BCV Pub. | F1: PRECIO $ G3Multi | G1: PRECIO $ BCV | H1: PRECIO Bs. | I1: UTILIDAD | J1: P. VENTA UTIL. | K1: diff.
A2: {=Roccia!A2:C997} -> ARTÍCULOS DE COCINA | B2: K001 | C2: JUEGO DE OLLAS DE GRANITO ANTIADHERENTE 12 PIEZAS DE LUJO NERO ROCCIA | D2: =IF(MOD(F2, 5) <= 2.5, FLOOR(F2, 5), CEILING(F2, 5)) -> 145 | E2: =IF(MOD(G2, 5) <= 2.5, FLOOR(G2, 5), CEILING(G2, 5)) -> 215 | F2: =IFERROR((VLOOKUP(B2, Roccia!$B$2:$D997, 3, FALSE)*(1+Datos!$E$1)), "Revisar") -> 143.403 | G2: =IFERROR(F2*Datos!$B$3, "Revisar") -> 215.1045 | H2: =IFERROR(G2*Datos!$B$1, "Revisar") -> 124232.77 | I2: =IFERROR((VLOOKUP(B2, Roccia!$B$2:$D997, 3, FALSE) /(1-Datos!$E$1)), "Revisar") -> 157.58571 | J2: =IFERROR(I2*Datos!$B$3, "Revisar") -> 236.37857 | K2: =IFERROR(J2-G2, "Revisar") -> 21.274071
A3: ARTÍCULOS DE COCINA | B3: K003 | C3: JUEGO DE SARTENES 3 PIEZAS NERO MARCA ROCCIA | D3: =IF(MOD(F3, 5) <= 2.5, FLOOR(F3, 5), CEILING(F3, 5)) -> 45 | E3: =IF(MOD(G3, 5) <= 2.5, FLOOR(G3, 5), CEILING(G3, 5)) -> 70 | F3: =IFERROR((VLOOKUP(B3, Roccia!$B$2:$D997, 3, FALSE)*(1+Datos!$E$1)), "Revisar") -> 46.982 | G3: =IFERROR(F3*Datos!$B$3, "Revisar") -> 70.473 | H3: =IFERROR(G3*Datos!$B$1, "Revisar") -> 40701.406 | I3: =IFERROR((VLOOKUP(B3, Roccia!$B$2:$D997, 3, FALSE) /(1-Datos!$E$1)), "Revisar") -> 51.628571 | J3: =IFERROR(I3*Datos!$B$3, "Revisar") -> 77.442857 | K3: =IFERROR(J3-G3, "Revisar") -> 6.9698571
A4: ARTÍCULOS DE COCINA | B4: K004 | C4: WOK DE 28CM CON TAPA DE CRISTAL MARCA ROCCIA | D4: =IF(MOD(F4, 5) <= 2.5, FLOOR(F4, 5), CEILING(F4, 5)) -> 30 | E4: =IF(MOD(G4, 5) <= 2.5, FLOOR(G4, 5), CEILING(G4, 5)) -> 40 | F4: =IFERROR((VLOOKUP(B4, Roccia!$B$2:$D997, 3, FALSE)*(1+Datos!$E$1)), "Revisar") -> 28.041 | G4: =IFERROR(F4*Datos!$B$3, "Revisar") -> 42.0615 | H4: =IFERROR(G4*Datos!$B$1, "Revisar") -> 24292.455 | I4: =IFERROR((VLOOKUP(B4, Roccia!$B$2:$D997, 3, FALSE) /(1-Datos!$E$1)), "Revisar") -> 30.814286 | J4: =IFERROR(I4*Datos!$B$3, "Revisar") -> 46.221429 | K4: =IFERROR(J4-G4, "Revisar") -> 4.1599286
A5: ARTÍCULOS DE COCINA | B5: K005 | C5: JUEGO DE OLLAS GRANITE 14 PIEZAS MARCA ROCCIA | D5: =IF(MOD(F5, 5) <= 2.5, FLOOR(F5, 5), CEILING(F5, 5)) -> 115 | E5: =IF(MOD(G5, 5) <= 2.5, FLOOR(G5, 5), CEILING(G5, 5)) -> 170 | F5: =IFERROR((VLOOKUP(B5, Roccia!$B$2:$D997, 3, FALSE)*(1+Datos!$E$1)), "Revisar") -> 113.815 | G5: =IFERROR(F5*Datos!$B$3, "Revisar") -> 170.7225 | H5: =IFERROR(G5*Datos!$B$1, "Revisar") -> 98600.114 | I5: =IFERROR((VLOOKUP(B5, Roccia!$B$2:$D997, 3, FALSE) /(1-Datos!$E$1)), "Revisar") -> 125.07143 | J5: =IFERROR(I5*Datos!$B$3, "Revisar") -> 187.60714 | K5: =IFERROR(J5-G5, "Revisar") -> 16.884643
A6: ARTÍCULOS DE COCINA | B6: K006 | C6: BUDARE 28CM CUADRADO NERO MARCA ROCCIA | D6: =IF(MOD(F6, 5) <= 2.5, FLOOR(F6, 5), CEILING(F6, 5)) -> 15 | E6: =IF(MOD(G6, 5) <= 2.5, FLOOR(G6, 5), CEILING(G6, 5)) -> 20 | F6: =IFERROR((VLOOKUP(B6, Roccia!$B$2:$D997, 3, FALSE)*(1+Datos!$E$1)), "Revisar") -> 14.287 | G6: =IFERROR(F6*Datos!$B$3, "Revisar") -> 21.4305 | H6: =IFERROR(G6*Datos!$B$1, "Revisar") -> 12377.102 | I6: =IFERROR((VLOOKUP(B6, Roccia!$B$2:$D997, 3, FALSE) /(1-Datos!$E$1)), "Revisar") -> 15.7 | J6: =IFERROR(I6*Datos!$B$3, "Revisar") -> 23.55 | K6: =IFERROR(J6-G6, "Revisar") -> 2.1195
A7: ARTÍCULOS DE COCINA | B7: K007G | C7: JUEGO DE UTENSILIOS DE COCINA 12 PIEZAS SILICONE ANTIRAYA GRIS | D7: =IF(MOD(F7, 5) <= 2.5, FLOOR(F7, 5), CEILING(F7, 5)) -> 15 | E7: =IF(MOD(G7, 5) <= 2.5, FLOOR(G7, 5), CEILING(G7, 5)) -> 20 | F7: =IFERROR((VLOOKUP(B7, Roccia!$B$2:$D997, 3, FALSE)*(1+Datos!$E$1)), "Revisar") -> 14.3 | G7: =IFERROR(F7*Datos!$B$3, "Revisar") -> 21.45 | H7: =IFERROR(G7*Datos!$B$1, "Revisar") -> 12388.364 | I7: =IFERROR((VLOOKUP(B7, Roccia!$B$2:$D997, 3, FALSE) /(1-Datos!$E$1)), "Revisar") -> 15.714286 | J7: =IFERROR(I7*Datos!$B$3, "Revisar") -> 23.571429 | K7: =IFERROR(J7-G7, "Revisar") -> 2.1214286
A8: ARTÍCULOS DE COCINA | B8: K007V | C8: JUEGO DE UTENSILIOS DE COCINA 12 PIEZAS SILICONE ANTIRAYA VERDE | D8: =IF(MOD(F8, 5) <= 2.5, FLOOR(F8, 5), CEILING(F8, 5)) -> 15 | E8: =IF(MOD(G8, 5) <= 2.5, FLOOR(G8, 5), CEILING(G8, 5)) -> 20 | F8: =IFERROR((VLOOKUP(B8, Roccia!$B$2:$D997, 3, FALSE)*(1+Datos!$E$1)), "Revisar") -> 14.3 | G8: =IFERROR(F8*Datos!$B$3, "Revisar") -> 21.45 | H8: =IFERROR(G8*Datos!$B$1, "Revisar") -> 12388.364 | I8: =IFERROR((VLOOKUP(B8, Roccia!$B$2:$D997, 3, FALSE) /(1-Datos!$E$1)), "Revisar") -> 15.714286 | J8: =IFERROR(I8*Datos!$B$3, "Revisar") -> 23.571429 | K8: =IFERROR(J8-G8, "Revisar") -> 2.1214286
A9: ARTÍCULOS DE COCINA | B9: K007N | C9: JUEGO DE UTENSILIOS DE COCINA 12 PIEZAS SILICONE ANTIRAYA NEGRO | D9: =IF(MOD(F9, 5) <= 2.5, FLOOR(F9, 5), CEILING(F9, 5)) -> 15 | E9: =IF(MOD(G9, 5) <= 2.5, FLOOR(G9, 5), CEILING(G9, 5)) -> 20 | F9: =IFERROR((VLOOKUP(B9, Roccia!$B$2:$D997, 3, FALSE)*(1+Datos!$E$1)), "Revisar") -> 14.3 | G9: =IFERROR(F9*Datos!$B$3, "Revisar") -> 21.45 | H9: =IFERROR(G9*Datos!$B$1, "Revisar") -> 12388.364 | I9: =IFERROR((VLOOKUP(B9, Roccia!$B$2:$D997, 3, FALSE) /(1-Datos!$E$1)), "Revisar") -> 15.714286 | J9: =IFERROR(I9*Datos!$B$3, "Revisar") -> 23.571429 | K9: =IFERROR(J9-G9, "Revisar") -> 2.1214286
A10: ARTÍCULOS DE COCINA | B10: K007B | C10: JUEGO DE UTENSILIOS DE COCINA 12 PIEZAS SILICONE ANTIRAYA BEIGE | D10: =IF(MOD(F10, 5) <= 2.5, FLOOR(F10, 5), CEILING(F10, 5)) -> 15 | E10: =IF(MOD(G10, 5) <= 2.5, FLOOR(G10, 5), CEILING(G10, 5)) -> 20 | F10: =IFERROR((VLOOKUP(B10, Roccia!$B$2:$D997, 3, FALSE)*(1+Datos!$E$1)), "Revisar") -> 14.3 | G10: =IFERROR(F10*Datos!$B$3, "Revisar") -> 21.45 | H10: =IFERROR(G10*Datos!$B$1, "Revisar") -> 12388.364 | I10: =IFERROR((VLOOKUP(B10, Roccia!$B$2:$D997, 3, FALSE) /(1-Datos!$E$1)), "Revisar") -> 15.714286 | J10: =IFERROR(I10*Datos!$B$3, "Revisar") -> 23.571429 | K10: =IFERROR(J10-G10, "Revisar") -> 2.1214286
A11: ARTÍCULOS DE COCINA | B11: K008 | C11: JUEGO DE 7 CUCHILLOS DE ALTA GAMA MARCA ROCCIA | D11: =IF(MOD(F11, 5) <= 2.5, FLOOR(F11, 5), CEILING(F11, 5)) -> 40 | E11: =IF(MOD(G11, 5) <= 2.5, FLOOR(G11, 5), CEILING(G11, 5)) -> 60 | F11: =IFERROR((VLOOKUP(B11, Roccia!$B$2:$D997, 3, FALSE)*(1+Datos!$E$1)), "Revisar") -> 40.183 | G11: =IFERROR(F11*Datos!$B$3, "Revisar") -> 60.2745 | H11: =IFERROR(G11*Datos!$B$1, "Revisar") -> 34811.302 | I11: =IFERROR((VLOOKUP(B11, Roccia!$B$2:$D997, 3, FALSE) /(1-Datos!$E$1)), "Revisar") -> 44.157143 | J11: =IFERROR(I11*Datos!$B$3, "Revisar") -> 66.235714 | K11: =IFERROR(J11-G11, "Revisar") -> 5.9612143
A12: ARTÍCULOS DE COCINA | B12: K009 | C12: JUEGO DE 5 CUCHILLOS DE ACERO INOXIDABLE | D12: =IF(MOD(F12, 5) <= 2.5, FLOOR(F12, 5), CEILING(F12, 5)) -> 20 | E12: =IF(MOD(G12, 5) <= 2.5, FLOOR(G12, 5), CEILING(G12, 5)) -> 30 | F12: =IFERROR((VLOOKUP(B12, Roccia!$B$2:$D997, 3, FALSE)*(1+Datos!$E$1)), "Revisar") -> 19.5 | G12: =IFERROR(F12*Datos!$B$3, "Revisar") -> 29.25 | H12: =IFERROR(G12*Datos!$B$1, "Revisar") -> 16893.223 | I12: =IFERROR((VLOOKUP(B12, Roccia!$B$2:$D997, 3, FALSE) /(1-Datos!$E$1)), "Revisar") -> 21.428571 | J12: =IFERROR(I12*Datos!$B$3, "Revisar") -> 32.142857 | K12: =IFERROR(J12-G12, "Revisar") -> 2.8928571
A13: ARTÍCULOS DE COCINA | B13: K010 | C13: SET DE OLLAS DILUSSO 8 PIEZAS DE ACERO INOXIDABLE MARCA ROCCIA | D13: =IF(MOD(F13, 5) <= 2.5, FLOOR(F13, 5), CEILING(F13, 5)) -> 130 | E13: =IF(MOD(G13, 5) <= 2.5, FLOOR(G13, 5), CEILING(G13, 5)) -> 195 | F13: =IFERROR((VLOOKUP(B13, Roccia!$B$2:$D997, 3, FALSE)*(1+Datos!$E$1)), "Revisar") -> 131.001 | G13: =IFERROR(F13*Datos!$B$3, "Revisar") -> 196.5015 | H13: =IFERROR(G13*Datos!$B$1, "Revisar") -> 113488.68 | I13: =IFERROR((VLOOKUP(B13, Roccia!$B$2:$D997, 3, FALSE) /(1-Datos!$E$1)), "Revisar") -> 143.95714 | J13: =IFERROR(I13*Datos!$B$3, "Revisar") -> 215.93571 | K13: =IFERROR(J13-G13, "Revisar") -> 19.434214
A14: ARTÍCULOS DE COCINA | B14: K011 | C14: JUEGO DE OLLAS GRANITE GRIS 14 PIEZAS EURO-14SET MARCA ROCCIA | D14: =IF(MOD(F14, 5) <= 2.5, FLOOR(F14, 5), CEILING(F14, 5)) -> 120 | E14: =IF(MOD(G14, 5) <= 2.5, FLOOR(G14, 5), CEILING(G14, 5)) -> 175 | F14: =IFERROR((VLOOKUP(B14, Roccia!$B$2:$D997, 3, FALSE)*(1+Datos!$E$1)), "Revisar") -> 117.741 | G14: =IFERROR(F14*Datos!$B$3, "Revisar") -> 176.6115 | H14: =IFERROR(G14*Datos!$B$1, "Revisar") -> 102001.28 | I14: =IFERROR((VLOOKUP(B14, Roccia!$B$2:$D997, 3, FALSE) /(1-Datos!$E$1)), "Revisar") -> 129.38571 | J14: =IFERROR(I14*Datos!$B$3, "Revisar") -> 194.07857 | K14: =IFERROR(J14-G14, "Revisar") -> 17.467071
A15: ARTÍCULOS DE COCINA | B15: K012 | C15: JUEGO DE OLLAS Di'ROCCA NEGRO 10 PIEZAS ALTA GAMA OF25-10PCS | D15: =IF(MOD(F15, 5) <= 2.5, FLOOR(F15, 5), CEILING(F15, 5)) -> 120 | E15: =IF(MOD(G15, 5) <= 2.5, FLOOR(G15, 5), CEILING(G15, 5)) -> 180 | F15: =IFERROR((VLOOKUP(B15, Roccia!$B$2:$D997, 3, FALSE)*(1+Datos!$E$1)), "Revisar") -> 119.08 | G15: =IFERROR(F15*Datos!$B$3, "Revisar") -> 178.62 | H15: =IFERROR(G15*Datos!$B$1, "Revisar") -> 103161.28 | I15: =IFERROR((VLOOKUP(B15, Roccia!$B$2:$D997, 3, FALSE) /(1-Datos!$E$1)), "Revisar") -> 130.85714 | J15: =IFERROR(I15*Datos!$B$3, "Revisar") -> 196.28571 | K15: =IFERROR(J15-G15, "Revisar") -> 17.665714
A16: ARTÍCULOS DE COCINA | B16: K013 | C16: JUEGO DE OLLAS Di'ROCCA BLANCO 10 PIEZAS ALTA GAMA OF26-10PCS | D16: =IF(MOD(F16, 5) <= 2.5, FLOOR(F16, 5), CEILING(F16, 5)) -> 120 | E16: =IF(MOD(G16, 5) <= 2.5, FLOOR(G16, 5), CEILING(G16, 5)) -> 180 | F16: =IFERROR((VLOOKUP(B16, Roccia!$B$2:$D997, 3, FALSE)*(1+Datos!$E$1)), "Revisar") -> 119.08 | G16: =IFERROR(F16*Datos!$B$3, "Revisar") -> 178.62 | H16: =IFERROR(G16*Datos!$B$1, "Revisar") -> 103161.28 | I16: =IFERROR((VLOOKUP(B16, Roccia!$B$2:$D997, 3, FALSE) /(1-Datos!$E$1)), "Revisar") -> 130.85714 | J16: =IFERROR(I16*Datos!$B$3, "Revisar") -> 196.28571 | K16: =IFERROR(J16-G16, "Revisar") -> 17.665714
A17: ARTICULOS PARA PISCINAS | B17: B029L | C17: LAMPARA LED PARA PISCINA 29.2*7CM CON BORDE 12W/12V YC292-A | D17: =IF(MOD(F17, 5) <= 2.5, FLOOR(F17, 5), CEILING(F17, 5)) -> 55 | E17: =IF(MOD(G17, 5) <= 2.5, FLOOR(G17, 5), CEILING(G17, 5)) -> 80 | F17: =IFERROR((VLOOKUP(B17, Roccia!$B$2:$D997, 3, FALSE)*(1+Datos!$E$1)), "Revisar") -> 52.663 | G17: =IFERROR(F17*Datos!$B$3, "Revisar") -> 78.9945 | H17: =IFERROR(G17*Datos!$B$1, "Revisar") -> 45622.965 | I17: =IFERROR((VLOOKUP(B17, Roccia!$B$2:$D997, 3, FALSE) /(1-Datos!$E$1)), "Revisar") -> 57.871429 | J17: =IFERROR(I17*Datos!$B$3, "Revisar") -> 86.807143 | K17: =IFERROR(J17-G17, "Revisar") -> 7.8126429
A18: ARTICULOS PARA PISCINAS | B18: B030L | C18: LAMPARA LED PARA PISCINA 29.5*7CM BORDE INFINITO 12W/12V YC295-2A | D18: =IF(MOD(F18, 5) <= 2.5, FLOOR(F18, 5), CEILING(F18, 5)) -> 55 | E18: =IF(MOD(G18, 5) <= 2.5, FLOOR(G18, 5), CEILING(G18, 5)) -> 85 | F18: =IFERROR((VLOOKUP(B18, Roccia!$B$2:$D997, 3, FALSE)*(1+Datos!$E$1)), "Revisar") -> 56.771 | G18: =IFERROR(F18*Datos!$B$3, "Revisar") -> 85.1565 | H18: =IFERROR(G18*Datos!$B$1, "Revisar") -> 49181.804 | I18: =IFERROR((VLOOKUP(B18, Roccia!$B$2:$D997, 3, FALSE) /(1-Datos!$E$1)), "Revisar") -> 62.385714 | J18: =IFERROR(I18*Datos!$B$3, "Revisar") -> 93.578571 | K18: =IFERROR(J18-G18, "Revisar") -> 8.4220714
A19: ARTICULOS PARA PISCINAS | B19: B031L | C19: LAMPARA LED PARA PISCINA 23*4.8CM 12W/12V YC230-2A | D19: =IF(MOD(F19, 5) <= 2.5, FLOOR(F19, 5), CEILING(F19, 5)) -> 55 | E19: =IF(MOD(G19, 5) <= 2.5, FLOOR(G19, 5), CEILING(G19, 5)) -> 80 | F19: =IFERROR((VLOOKUP(B19, Roccia!$B$2:$D997, 3, FALSE)*(1+Datos!$E$1)), "Revisar") -> 52.624 | G19: =IFERROR(F19*Datos!$B$3, "Revisar") -> 78.936 | H19: =IFERROR(G19*Datos!$B$1, "Revisar") -> 45589.179 | I19: =IFERROR((VLOOKUP(B19, Roccia!$B$2:$D997, 3, FALSE) /(1-Datos!$E$1)), "Revisar") -> 57.828571 | J19: =IFERROR(I19*Datos!$B$3, "Revisar") -> 86.742857 | K19: =IFERROR(J19-G19, "Revisar") -> 7.8068571
A20: ARTICULOS PARA PISCINAS | B20: B032L | C20: LAMPARA LED PARA PISCINA 23*4.8CM 12W/12V YC230-SW | D20: =IF(MOD(F20, 5) <= 2.5, FLOOR(F20, 5), CEILING(F20, 5)) -> 55 | E20: =IF(MOD(G20, 5) <= 2.5, FLOOR(G20, 5), CEILING(G20, 5)) -> 80 | F20: =IFERROR((VLOOKUP(B20, Roccia!$B$2:$D997, 3, FALSE)*(1+Datos!$E$1)), "Revisar") -> 52.663 | G20: =IFERROR(F20*Datos!$B$3, "Revisar") -> 78.9945 | H20: =IFERROR(G20*Datos!$B$1, "Revisar") -> 45622.965 | I20: =IFERROR((VLOOKUP(B20, Roccia!$B$2:$D997, 3, FALSE) /(1-Datos!$E$1)), "Revisar") -> 57.871429 | J20: =IFERROR(I20*Datos!$B$3, "Revisar") -> 86.807143 | K20: =IFERROR(J20-G20, "Revisar") -> 7.8126429
A21: ARTICULOS PARA PISCINAS | B21: B033L | C21: LAMPARA LED PARA PISCINA 30*7CM 18W/12V YC300-SW | D21: =IF(MOD(F21, 5) <= 2.5, FLOOR(F21, 5), CEILING(F21, 5)) -> 75 | E21: =IF(MOD(G21, 5) <= 2.5, FLOOR(G21, 5), CEILING(G21, 5)) -> 115 | F21: =IFERROR((VLOOKUP(B21, Roccia!$B$2:$D997, 3, FALSE)*(1+Datos!$E$1)), "Revisar") -> 76.076 | G21: =IFERROR(F21*Datos!$B$3, "Revisar") -> 114.114 | H21: =IFERROR(G21*Datos!$B$1, "Revisar") -> 65906.096 | I21: =IFERROR((VLOOKUP(B21, Roccia!$B$2:$D997, 3, FALSE) /(1-Datos!$E$1)), "Revisar") -> 83.6 | J21: =IFERROR(I21*Datos!$B$3, "Revisar") -> 125.4 | K21: =IFERROR(J21-G21, "Revisar") -> 11.286
A22: ARTICULOS PARA PISCINAS | B22: B034L | C22: ASPIRADORA DE PISCINAS RECARGABLE 2000MAH 40W RPC403 MARCA ROCCIA | D22: =IF(MOD(F22, 5) <= 2.5, FLOOR(F22, 5), CEILING(F22, 5)) -> 115 | E22: =IF(MOD(G22, 5) <= 2.5, FLOOR(G22, 5), CEILING(G22, 5)) -> 175 | F22: =IFERROR((VLOOKUP(B22, Roccia!$B$2:$D997, 3, FALSE)*(1+Datos!$E$1)), "Revisar") -> 116.415 | G22: =IFERROR(F22*Datos!$B$3, "Revisar") -> 174.6225 | H22: =IFERROR(G22*Datos!$B$1, "Revisar") -> 100852.54 | I22: =IFERROR((VLOOKUP(B22, Roccia!$B$2:$D997, 3, FALSE) /(1-Datos!$E$1)), "Revisar") -> 127.92857 | J22: =IFERROR(I22*Datos!$B$3, "Revisar") -> 191.89286 | K22: =IFERROR(J22-G22, "Revisar") -> 17.270357
A23: ARTICULOS PARA PISCINAS | B23: B035L | C23: CLORIFICADOR SALINO INTELIGENTE 25g/h PARA PISCINAS LC250A | D23: =IF(MOD(F23, 5) <= 2.5, FLOOR(F23, 5), CEILING(F23, 5)) -> 505 | E23: =IF(MOD(G23, 5) <= 2.5, FLOOR(G23, 5), CEILING(G23, 5)) -> 755 | F23: =IFERROR((VLOOKUP(B23, Roccia!$B$2:$D997, 3, FALSE)*(1+Datos!$E$1)), "Revisar") -> 502.84 | G23: =IFERROR(F23*Datos!$B$3, "Revisar") -> 754.26 | H23: =IFERROR(G23*Datos!$B$1, "Revisar") -> 435619.92 | I23: =IFERROR((VLOOKUP(B23, Roccia!$B$2:$D997, 3, FALSE) /(1-Datos!$E$1)), "Revisar") -> 552.57143 | J23: =IFERROR(I23*Datos!$B$3, "Revisar") -> 828.85714 | K23: =IFERROR(J23-G23, "Revisar") -> 74.597143
A24: ARTICULOS PARA PISCINAS | B24: B036L | C24: CLORIFICADOR SALINO INTELIGENTE 30g/h PARA PISCINAS LC300A | D24: =IF(MOD(F24, 5) <= 2.5, FLOOR(F24, 5), CEILING(F24, 5)) -> 570 | E24: =IF(MOD(G24, 5) <= 2.5, FLOOR(G24, 5), CEILING(G24, 5)) -> 855 | F24: =IFERROR((VLOOKUP(B24, Roccia!$B$2:$D997, 3, FALSE)*(1+Datos!$E$1)), "Revisar") -> 569.179 | G24: =IFERROR(F24*Datos!$B$3, "Revisar") -> 853.7685 | H24: =IFERROR(G24*Datos!$B$1, "Revisar") -> 493090.67 | I24: =IFERROR((VLOOKUP(B24, Roccia!$B$2:$D997, 3, FALSE) /(1-Datos!$E$1)), "Revisar") -> 625.47143 | J24: =IFERROR(I24*Datos!$B$3, "Revisar") -> 938.20714 | K24: =IFERROR(J24-G24, "Revisar") -> 84.438643
A25: ARTICULOS PARA PISCINAS | B25: B037L | C25: CLORIFICADOR SALINO INTELIGENTE 40g/h PARA PISCINAS LC400A | D25: =IF(MOD(F25, 5) <= 2.5, FLOOR(F25, 5), CEILING(F25, 5)) -> 725 | E25: =IF(MOD(G25, 5) <= 2.5, FLOOR(G25, 5), CEILING(G25, 5)) -> 1090 | F25: =IFERROR((VLOOKUP(B25, Roccia!$B$2:$D997, 3, FALSE)*(1+Datos!$E$1)), "Revisar") -> 727.363 | G25: =IFERROR(F25*Datos!$B$3, "Revisar") -> 1091.0445 | H25: =IFERROR(G25*Datos!$B$1, "Revisar") -> 630128.5 | I25: =IFERROR((VLOOKUP(B25, Roccia!$B$2:$D997, 3, FALSE) /(1-Datos!$E$1)), "Revisar") -> 799.3 | J25: =IFERROR(I25*Datos!$B$3, "Revisar") -> 1198.95 | K25: =IFERROR(J25-G25, "Revisar") -> 107.9055
A26: ARTICULOS PARA PISCINAS | B26: B038L | C26: CLORIFICADOR SALINO INTELIGENTE 50g/h PARA PISCINAS LC500A | D26: =IF(MOD(F26, 5) <= 2.5, FLOOR(F26, 5), CEILING(F26, 5)) -> 885 | E26: =IF(MOD(G26, 5) <= 2.5, FLOOR(G26, 5), CEILING(G26, 5)) -> 1325 | F26: =IFERROR((VLOOKUP(B26, Roccia!$B$2:$D997, 3, FALSE)*(1+Datos!$E$1)), "Revisar") -> 883.012 | G26: =IFERROR(F26*Datos!$B$3, "Revisar") -> 1324.518 | H26: =IFERROR(G26*Datos!$B$1, "Revisar") -> 764970.21 | I26: =IFERROR((VLOOKUP(B26, Roccia!$B$2:$D997, 3, FALSE) /(1-Datos!$E$1)), "Revisar") -> 970.34286 | J26: =IFERROR(I26*Datos!$B$3, "Revisar") -> 1455.5143 | K26: =IFERROR(J26-G26, "Revisar") -> 130.99629
A27: BALANZAS | B27: P001 | C27: BALANZA DE 40 KG | D27: =IF(MOD(F27, 5) <= 2.5, FLOOR(F27, 5), CEILING(F27, 5)) -> 35 | E27: =IF(MOD(G27, 5) <= 2.5, FLOOR(G27, 5), CEILING(G27, 5)) -> 50 | F27: =IFERROR((VLOOKUP(B27, Roccia!$B$2:$D997, 3, FALSE)*(1+Datos!$E$1)), "Revisar") -> 33.8 | G27: =IFERROR(F27*Datos!$B$3, "Revisar") -> 50.7 | H27: =IFERROR(G27*Datos!$B$1, "Revisar") -> 29281.587 | I27: =IFERROR((VLOOKUP(B27, Roccia!$B$2:$D997, 3, FALSE) /(1-Datos!$E$1)), "Revisar") -> 37.142857 | J27: =IFERROR(I27*Datos!$B$3, "Revisar") -> 55.714286 | K27: =IFERROR(J27-G27, "Revisar") -> 5.0142857
A28: BALANZAS | B28: P003 | C28: BALANZA DE 7 KG | D28: =IF(MOD(F28, 5) <= 2.5, FLOOR(F28, 5), CEILING(F28, 5)) -> 5 | E28: =IF(MOD(G28, 5) <= 2.5, FLOOR(G28, 5), CEILING(G28, 5)) -> 5 | F28: =IFERROR((VLOOKUP(B28, Roccia!$B$2:$D997, 3, FALSE)*(1+Datos!$E$1)), "Revisar") -> 4.55 | G28: =IFERROR(F28*Datos!$B$3, "Revisar") -> 6.825 | H28: =IFERROR(G28*Datos!$B$1, "Revisar") -> 3941.7521 | I28: =IFERROR((VLOOKUP(B28, Roccia!$B$2:$D997, 3, FALSE) /(1-Datos!$E$1)), "Revisar") -> 5 | J28: =IFERROR(I28*Datos!$B$3, "Revisar") -> 7.5 | K28: =IFERROR(J28-G28, "Revisar") -> 0.675
A29: BALANZAS | B29: P011 | C29: ROMANA DE 200 KG | D29: =IF(MOD(F29, 5) <= 2.5, FLOOR(F29, 5), CEILING(F29, 5)) -> 55 | E29: =IF(MOD(G29, 5) <= 2.5, FLOOR(G29, 5), CEILING(G29, 5)) -> 80 | F29: =IFERROR((VLOOKUP(B29, Roccia!$B$2:$D997, 3, FALSE)*(1+Datos!$E$1)), "Revisar") -> 54.6 | G29: =IFERROR(F29*Datos!$B$3, "Revisar") -> 81.9 | H29: =IFERROR(G29*Datos!$B$1, "Revisar") -> 47301.026 | I29: =IFERROR((VLOOKUP(B29, Roccia!$B$2:$D997, 3, FALSE) /(1-Datos!$E$1)), "Revisar") -> 60 | J29: =IFERROR(I29*Datos!$B$3, "Revisar") -> 90 | K29: =IFERROR(J29-G29, "Revisar") -> 8.1
A30: BALANZAS | B30: P012 | C30: ROMANA DE 350 KG | D30: =IF(MOD(F30, 5) <= 2.5, FLOOR(F30, 5), CEILING(F30, 5)) -> 80 | E30: =IF(MOD(G30, 5) <= 2.5, FLOOR(G30, 5), CEILING(G30, 5)) -> 115 | F30: =IFERROR((VLOOKUP(B30, Roccia!$B$2:$D997, 3, FALSE)*(1+Datos!$E$1)), "Revisar") -> 78 | G30: =IFERROR(F30*Datos!$B$3, "Revisar") -> 117 | H30: =IFERROR(G30*Datos!$B$1, "Revisar") -> 67572.894 | I30: =IFERROR((VLOOKUP(B30, Roccia!$B$2:$D997, 3, FALSE) /(1-Datos!$E$1)), "Revisar") -> 85.714286 | J30: =IFERROR(I30*Datos!$B$3, "Revisar") -> 128.57143 | K30: =IFERROR(J30-G30, "Revisar") -> 11.571429
A31: BALANZAS | B31: P013 | C31: ROMANA DE 700 KG | D31: =IF(MOD(F31, 5) <= 2.5, FLOOR(F31, 5), CEILING(F31, 5)) -> 130 | E31: =IF(MOD(G31, 5) <= 2.5, FLOOR(G31, 5), CEILING(G31, 5)) -> 195 | F31: =IFERROR((VLOOKUP(B31, Roccia!$B$2:$D997, 3, FALSE)*(1+Datos!$E$1)), "Revisar") -> 130 | G31: =IFERROR(F31*Datos!$B$3, "Revisar") -> 195 | H31: =IFERROR(G31*Datos!$B$1, "Revisar") -> 112621.49 | I31: =IFERROR((VLOOKUP(B31, Roccia!$B$2:$D997, 3, FALSE) /(1-Datos!$E$1)), "Revisar") -> 142.85714 | J31: =IFERROR(I31*Datos!$B$3, "Revisar") -> 214.28571 | K31: =IFERROR(J31-G31, "Revisar") -> 19.285714
A32: BALANZAS | B32: P014 | C32: ROMANA WIFI 300 KG | D32: =IF(MOD(F32, 5) <= 2.5, FLOOR(F32, 5), CEILING(F32, 5)) -> 95 | E32: =IF(MOD(G32, 5) <= 2.5, FLOOR(G32, 5), CEILING(G32, 5)) -> 145 | F32: =IFERROR((VLOOKUP(B32, Roccia!$B$2:$D997, 3, FALSE)*(1+Datos!$E$1)), "Revisar") -> 95.095 | G32: =IFERROR(F32*Datos!$B$3, "Revisar") -> 142.6425 | H32: =IFERROR(G32*Datos!$B$1, "Revisar") -> 82382.62 | I32: =IFERROR((VLOOKUP(B32, Roccia!$B$2:$D997, 3, FALSE) /(1-Datos!$E$1)), "Revisar") -> 104.5 | J32: =IFERROR(I32*Datos!$B$3, "Revisar") -> 156.75 | K32: =IFERROR(J32-G32, "Revisar") -> 14.1075
A33: BALANZAS | B33: P016 | C33: ROMANA DE 3T 1*1 | D33: =IF(MOD(F33, 5) <= 2.5, FLOOR(F33, 5), CEILING(F33, 5)) -> 485 | E33: =IF(MOD(G33, 5) <= 2.5, FLOOR(G33, 5), CEILING(G33, 5)) -> 730 | F33: =IFERROR((VLOOKUP(B33, Roccia!$B$2:$D997, 3, FALSE)*(1+Datos!$E$1)), "Revisar") -> 485.849 | G33: =IFERROR(F33*Datos!$B$3, "Revisar") -> 728.7735 | H33: =IFERROR(G33*Datos!$B$1, "Revisar") -> 420900.29 | I33: =IFERROR((VLOOKUP(B33, Roccia!$B$2:$D997, 3, FALSE) /(1-Datos!$E$1)), "Revisar") -> 533.9 | J33: =IFERROR(I33*Datos!$B$3, "Revisar") -> 800.85 | K33: =IFERROR(J33-G33, "Revisar") -> 72.0765
A34: BALANZAS | B34: P017 | C34: ROMANA DE 3T 1,20*1,20 | D34: =IF(MOD(F34, 5) <= 2.5, FLOOR(F34, 5), CEILING(F34, 5)) -> 515 | E34: =IF(MOD(G34, 5) <= 2.5, FLOOR(G34, 5), CEILING(G34, 5)) -> 775 | F34: =IFERROR((VLOOKUP(B34, Roccia!$B$2:$D997, 3, FALSE)*(1+Datos!$E$1)), "Revisar") -> 515.489 | G34: =IFERROR(F34*Datos!$B$3, "Revisar") -> 773.2335 | H34: =IFERROR(G34*Datos!$B$1, "Revisar") -> 446577.99 | I34: =IFERROR((VLOOKUP(B34, Roccia!$B$2:$D997, 3, FALSE) /(1-Datos!$E$1)), "Revisar") -> 566.47143 | J34: =IFERROR(I34*Datos!$B$3, "Revisar") -> 849.70714 | K34: =IFERROR(J34-G34, "Revisar") -> 76.473643
A35: BALANZAS | B35: P018 | C35: ROMANA DE 3T 1,50*2 | D35: =IF(MOD(F35, 5) <= 2.5, FLOOR(F35, 5), CEILING(F35, 5)) -> 850 | E35: =IF(MOD(G35, 5) <= 2.5, FLOOR(G35, 5), CEILING(G35, 5)) -> 1275 | F35: =IFERROR((VLOOKUP(B35, Roccia!$B$2:$D997, 3, FALSE)*(1+Datos!$E$1)), "Revisar") -> 848.926 | G35: =IFERROR(F35*Datos!$B$3, "Revisar") -> 1273.389 | H35: =IFERROR(G35*Datos!$B$1, "Revisar") -> 735440.85 | I35: =IFERROR((VLOOKUP(B35, Roccia!$B$2:$D997, 3, FALSE) /(1-Datos!$E$1)), "Revisar") -> 932.88571 | J35: =IFERROR(I35*Datos!$B$3, "Revisar") -> 1399.3286 | K35: =IFERROR(J35-G35, "Revisar") -> 125.93957
A36: BALANZAS | B36: P019 | C36: BALANZA DE GANCHO RECARGABLE 50KG GOOD QUALITY YZ-S03 | D36: =IF(MOD(F36, 5) <= 2.5, FLOOR(F36, 5), CEILING(F36, 5)) -> 10 | E36: =IF(MOD(G36, 5) <= 2.5, FLOOR(G36, 5), CEILING(G36, 5)) -> 15 | F36: =IFERROR((VLOOKUP(B36, Roccia!$B$2:$D997, 3, FALSE)*(1+Datos!$E$1)), "Revisar") -> 9.1 | G36: =IFERROR(F36*Datos!$B$3, "Revisar") -> 13.65 | H36: =IFERROR(G36*Datos!$B$1, "Revisar") -> 7883.5043 | I36: =IFERROR((VLOOKUP(B36, Roccia!$B$2:$D997, 3, FALSE) /(1-Datos!$E$1)), "Revisar") -> 10 | J36: =IFERROR(I36*Datos!$B$3, "Revisar") -> 15 | K36: =IFERROR(J36-G36, "Revisar") -> 1.35
A37: BALANZAS | B37: P020 | C37: BALANZA DE COCINA 3KG GOOD QUALITY X1-C3B | D37: =IF(MOD(F37, 5) <= 2.5, FLOOR(F37, 5), CEILING(F37, 5)) -> 20 | E37: =IF(MOD(G37, 5) <= 2.5, FLOOR(G37, 5), CEILING(G37, 5)) -> 30 | F37: =IFERROR((VLOOKUP(B37, Roccia!$B$2:$D997, 3, FALSE)*(1+Datos!$E$1)), "Revisar") -> 19.175 | G37: =IFERROR(F37*Datos!$B$3, "Revisar") -> 28.7625 | H37: =IFERROR(G37*Datos!$B$1, "Revisar") -> 16611.67 | I37: =IFERROR((VLOOKUP(B37, Roccia!$B$2:$D997, 3, FALSE) /(1-Datos!$E$1)), "Revisar") -> 21.071429 | J37: =IFERROR(I37*Datos!$B$3, "Revisar") -> 31.607143 | K37: =IFERROR(J37-G37, "Revisar") -> 2.8446429
A38: BALANZAS | B38: P021 | C38: BALANZA DE MOSTRADOR CAP 30KG DE ALTA PRECISION 905 | D38: =IF(MOD(F38, 5) <= 2.5, FLOOR(F38, 5), CEILING(F38, 5)) -> 45 | E38: =IF(MOD(G38, 5) <= 2.5, FLOOR(G38, 5), CEILING(G38, 5)) -> 65 | F38: =IFERROR((VLOOKUP(B38, Roccia!$B$2:$D997, 3, FALSE)*(1+Datos!$E$1)), "Revisar") -> 44.382 | G38: =IFERROR(F38*Datos!$B$3, "Revisar") -> 66.573 | H38: =IFERROR(G38*Datos!$B$1, "Revisar") -> 38448.977 | I38: =IFERROR((VLOOKUP(B38, Roccia!$B$2:$D997, 3, FALSE) /(1-Datos!$E$1)), "Revisar") -> 48.771429 | J38: =IFERROR(I38*Datos!$B$3, "Revisar") -> 73.157143 | K38: =IFERROR(J38-G38, "Revisar") -> 6.5841429
A39: BALANZAS | B39: P021S | C39: BALANZA DE MOSTRADOR CAP 30KG DE ALTA PRECISION 905 CON SENCAMER | D39: =IF(MOD(F39, 5) <= 2.5, FLOOR(F39, 5), CEILING(F39, 5)) -> 80 | E39: =IF(MOD(G39, 5) <= 2.5, FLOOR(G39, 5), CEILING(G39, 5)) -> 115 | F39: =IFERROR((VLOOKUP(B39, Roccia!$B$2:$D997, 3, FALSE)*(1+Datos!$E$1)), "Revisar") -> 78 | G39: =IFERROR(F39*Datos!$B$3, "Revisar") -> 117 | H39: =IFERROR(G39*Datos!$B$1, "Revisar") -> 67572.894 | I39: =IFERROR((VLOOKUP(B39, Roccia!$B$2:$D997, 3, FALSE) /(1-Datos!$E$1)), "Revisar") -> 85.714286 | J39: =IFERROR(I39*Datos!$B$3, "Revisar") -> 128.57143 | K39: =IFERROR(J39-G39, "Revisar") -> 11.571429
A40: BALANZAS | B40: P022 | C40: BALANZA DE MOSTRADOR CON SU VISOR CAP 30KG DE ALTA PRECISION 905ARM | D40: =IF(MOD(F40, 5) <= 2.5, FLOOR(F40, 5), CEILING(F40, 5)) -> 60 | E40: =IF(MOD(G40, 5) <= 2.5, FLOOR(G40, 5), CEILING(G40, 5)) -> 90 | F40: =IFERROR((VLOOKUP(B40, Roccia!$B$2:$D997, 3, FALSE)*(1+Datos!$E$1)), "Revisar") -> 58.734 | G40: =IFERROR(F40*Datos!$B$3, "Revisar") -> 88.101 | H40: =IFERROR(G40*Datos!$B$1, "Revisar") -> 50882.389 | I40: =IFERROR((VLOOKUP(B40, Roccia!$B$2:$D997, 3, FALSE) /(1-Datos!$E$1)), "Revisar") -> 64.542857 | J40: =IFERROR(I40*Datos!$B$3, "Revisar") -> 96.814286 | K40: =IFERROR(J40-G40, "Revisar") -> 8.7132857
...

Sheet G3 Multi - Ajuste
A1: TIPO | B1: CODIGO | C1: PRODUCTO | D1: PRECIO $ G3Multi | E1: PRECIO $ BCV | F1: PRECIO Bs. | G1: UTILIDAD | H1: P. VENTA UTIL. | I1: diff.
A2: {=Roccia!A2:C997} -> ARTÍCULOS DE COCINA | B2: K001 | C2: JUEGO DE OLLAS DE GRANITO ANTIADHERENTE 12 PIEZAS DE LUJO NERO ROCCIA | D2: =IFERROR((VLOOKUP(B2, Roccia!$B$2:$D997, 3, FALSE)*(1+Datos!$E$2)), "Revisar") -> 132.372 | E2: =IFERROR(D2*Datos!$B$3, "Revisar") -> 198.558 | F2: =IFERROR(E2*Datos!$B$1, "Revisar") -> 114676.4 | G2: =IFERROR((VLOOKUP(B2, Roccia!$B$2:$D997, 3, FALSE) /(1-Datos!$E$1)), "Revisar") -> 157.58571 | H2: =IFERROR(G2*Datos!$B$3, "Revisar") -> 236.37857 | I2: =IFERROR(H2-E2, "Revisar") -> 37.820571
A3: ARTÍCULOS DE COCINA | B3: K003 | C3: JUEGO DE SARTENES 3 PIEZAS NERO MARCA ROCCIA | D3: =IFERROR((VLOOKUP(B3, Roccia!$B$2:$D997, 3, FALSE)*(1+Datos!$E$2)), "Revisar") -> 43.368 | E3: =IFERROR(D3*Datos!$B$3, "Revisar") -> 65.052 | F3: =IFERROR(E3*Datos!$B$1, "Revisar") -> 37570.529 | G3: =IFERROR((VLOOKUP(B3, Roccia!$B$2:$D997, 3, FALSE) /(1-Datos!$E$1)), "Revisar") -> 51.628571 | H3: =IFERROR(G3*Datos!$B$3, "Revisar") -> 77.442857 | I3: =IFERROR(H3-E3, "Revisar") -> 12.390857
A4: ARTÍCULOS DE COCINA | B4: K004 | C4: WOK DE 28CM CON TAPA DE CRISTAL MARCA ROCCIA | D4: =IFERROR((VLOOKUP(B4, Roccia!$B$2:$D997, 3, FALSE)*(1+Datos!$E$2)), "Revisar") -> 25.884 | E4: =IFERROR(D4*Datos!$B$3, "Revisar") -> 38.826 | F4: =IFERROR(E4*Datos!$B$1, "Revisar") -> 22423.805 | G4: =IFERROR((VLOOKUP(B4, Roccia!$B$2:$D997, 3, FALSE) /(1-Datos!$E$1)), "Revisar") -> 30.814286 | H4: =IFERROR(G4*Datos!$B$3, "Revisar") -> 46.221429 | I4: =IFERROR(H4-E4, "Revisar") -> 7.3954286
A5: ARTÍCULOS DE COCINA | B5: K005 | C5: JUEGO DE OLLAS GRANITE 14 PIEZAS MARCA ROCCIA | D5: =IFERROR((VLOOKUP(B5, Roccia!$B$2:$D997, 3, FALSE)*(1+Datos!$E$2)), "Revisar") -> 105.06 | E5: =IFERROR(D5*Datos!$B$3, "Revisar") -> 157.59 | F5: =IFERROR(E5*Datos!$B$1, "Revisar") -> 91015.49 | G5: =IFERROR((VLOOKUP(B5, Roccia!$B$2:$D997, 3, FALSE) /(1-Datos!$E$1)), "Revisar") -> 125.07143 | H5: =IFERROR(G5*Datos!$B$3, "Revisar") -> 187.60714 | I5: =IFERROR(H5-E5, "Revisar") -> 30.017143
A6: ARTÍCULOS DE COCINA | B6: K006 | C6: BUDARE 28CM CUADRADO NERO MARCA ROCCIA | D6: =IFERROR((VLOOKUP(B6, Roccia!$B$2:$D997, 3, FALSE)*(1+Datos!$E$2)), "Revisar") -> 13.188 | E6: =IFERROR(D6*Datos!$B$3, "Revisar") -> 19.782 | F6: =IFERROR(E6*Datos!$B$1, "Revisar") -> 11425.017 | G6: =IFERROR((VLOOKUP(B6, Roccia!$B$2:$D997, 3, FALSE) /(1-Datos!$E$1)), "Revisar") -> 15.7 | H6: =IFERROR(G6*Datos!$B$3, "Revisar") -> 23.55 | I6: =IFERROR(H6-E6, "Revisar") -> 3.768
A7: ARTÍCULOS DE COCINA | B7: K007G | C7: JUEGO DE UTENSILIOS DE COCINA 12 PIEZAS SILICONE ANTIRAYA GRIS | D7: =IFERROR((VLOOKUP(B7, Roccia!$B$2:$D997, 3, FALSE)*(1+Datos!$E$2)), "Revisar") -> 13.2 | E7: =IFERROR(D7*Datos!$B$3, "Revisar") -> 19.8 | F7: =IFERROR(E7*Datos!$B$1, "Revisar") -> 11435.413 | G7: =IFERROR((VLOOKUP(B7, Roccia!$B$2:$D997, 3, FALSE) /(1-Datos!$E$1)), "Revisar") -> 15.714286 | H7: =IFERROR(G7*Datos!$B$3, "Revisar") -> 23.571429 | I7: =IFERROR(H7-E7, "Revisar") -> 3.7714286
A8: ARTÍCULOS DE COCINA | B8: K007V | C8: JUEGO DE UTENSILIOS DE COCINA 12 PIEZAS SILICONE ANTIRAYA VERDE | D8: =IFERROR((VLOOKUP(B8, Roccia!$B$2:$D997, 3, FALSE)*(1+Datos!$E$2)), "Revisar") -> 13.2 | E8: =IFERROR(D8*Datos!$B$3, "Revisar") -> 19.8 | F8: =IFERROR(E8*Datos!$B$1, "Revisar") -> 11435.413 | G8: =IFERROR((VLOOKUP(B8, Roccia!$B$2:$D997, 3, FALSE) /(1-Datos!$E$1)), "Revisar") -> 15.714286 | H8: =IFERROR(G8*Datos!$B$3, "Revisar") -> 23.571429 | I8: =IFERROR(H8-E8, "Revisar") -> 3.7714286
A9: ARTÍCULOS DE COCINA | B9: K007N | C9: JUEGO DE UTENSILIOS DE COCINA 12 PIEZAS SILICONE ANTIRAYA NEGRO | D9: =IFERROR((VLOOKUP(B9, Roccia!$B$2:$D997, 3, FALSE)*(1+Datos!$E$2)), "Revisar") -> 13.2 | E9: =IFERROR(D9*Datos!$B$3, "Revisar") -> 19.8 | F9: =IFERROR(E9*Datos!$B$1, "Revisar") -> 11435.413 | G9: =IFERROR((VLOOKUP(B9, Roccia!$B$2:$D997, 3, FALSE) /(1-Datos!$E$1)), "Revisar") -> 15.714286 | H9: =IFERROR(G9*Datos!$B$3, "Revisar") -> 23.571429 | I9: =IFERROR(H9-E9, "Revisar") -> 3.7714286
A10: ARTÍCULOS DE COCINA | B10: K007B | C10: JUEGO DE UTENSILIOS DE COCINA 12 PIEZAS SILICONE ANTIRAYA BEIGE | D10: =IFERROR((VLOOKUP(B10, Roccia!$B$2:$D997, 3, FALSE)*(1+Datos!$E$2)), "Revisar") -> 13.2 | E10: =IFERROR(D10*Datos!$B$3, "Revisar") -> 19.8 | F10: =IFERROR(E10*Datos!$B$1, "Revisar") -> 11435.413 | G10: =IFERROR((VLOOKUP(B10, Roccia!$B$2:$D997, 3, FALSE) /(1-Datos!$E$1)), "Revisar") -> 15.714286 | H10: =IFERROR(G10*Datos!$B$3, "Revisar") -> 23.571429 | I10: =IFERROR(H10-E10, "Revisar") -> 3.7714286
A11: ARTÍCULOS DE COCINA | B11: K008 | C11: JUEGO DE 7 CUCHILLOS DE ALTA GAMA MARCA ROCCIA | D11: =IFERROR((VLOOKUP(B11, Roccia!$B$2:$D997, 3, FALSE)*(1+Datos!$E$2)), "Revisar") -> 37.092 | E11: =IFERROR(D11*Datos!$B$3, "Revisar") -> 55.638 | F11: =IFERROR(E11*Datos!$B$1, "Revisar") -> 32133.51 | G11: =IFERROR((VLOOKUP(B11, Roccia!$B$2:$D997, 3, FALSE) /(1-Datos!$E$1)), "Revisar") -> 44.157143 | H11: =IFERROR(G11*Datos!$B$3, "Revisar") -> 66.235714 | I11: =IFERROR(H11-E11, "Revisar") -> 10.597714
A12: ARTÍCULOS DE COCINA | B12: K009 | C12: JUEGO DE 5 CUCHILLOS DE ACERO INOXIDABLE | D12: =IFERROR((VLOOKUP(B12, Roccia!$B$2:$D997, 3, FALSE)*(1+Datos!$E$2)), "Revisar") -> 18 | E12: =IFERROR(D12*Datos!$B$3, "Revisar") -> 27 | F12: =IFERROR(E12*Datos!$B$1, "Revisar") -> 15593.745 | G12: =IFERROR((VLOOKUP(B12, Roccia!$B$2:$D997, 3, FALSE) /(1-Datos!$E$1)), "Revisar") -> 21.428571 | H12: =IFERROR(G12*Datos!$B$3, "Revisar") -> 32.142857 | I12: =IFERROR(H12-E12, "Revisar") -> 5.1428571
A13: ARTÍCULOS DE COCINA | B13: K010 | C13: SET DE OLLAS DILUSSO 8 PIEZAS DE ACERO INOXIDABLE MARCA ROCCIA | D13: =IFERROR((VLOOKUP(B13, Roccia!$B$2:$D997, 3, FALSE)*(1+Datos!$E$2)), "Revisar") -> 120.924 | E13: =IFERROR(D13*Datos!$B$3, "Revisar") -> 181.386 | F13: =IFERROR(E13*Datos!$B$1, "Revisar") -> 104758.78 | G13: =IFERROR((VLOOKUP(B13, Roccia!$B$2:$D997, 3, FALSE) /(1-Datos!$E$1)), "Revisar") -> 143.95714 | H13: =IFERROR(G13*Datos!$B$3, "Revisar") -> 215.93571 | I13: =IFERROR(H13-E13, "Revisar") -> 34.549714
A14: ARTÍCULOS DE COCINA | B14: K011 | C14: JUEGO DE OLLAS GRANITE GRIS 14 PIEZAS EURO-14SET MARCA ROCCIA | D14: =IFERROR((VLOOKUP(B14, Roccia!$B$2:$D997, 3, FALSE)*(1+Datos!$E$2)), "Revisar") -> 108.684 | E14: =IFERROR(D14*Datos!$B$3, "Revisar") -> 163.026 | F14: =IFERROR(E14*Datos!$B$1, "Revisar") -> 94155.03 | G14: =IFERROR((VLOOKUP(B14, Roccia!$B$2:$D997, 3, FALSE) /(1-Datos!$E$1)), "Revisar") -> 129.38571 | H14: =IFERROR(G14*Datos!$B$3, "Revisar") -> 194.07857 | I14: =IFERROR(H14-E14, "Revisar") -> 31.052571
A15: ARTÍCULOS DE COCINA | B15: K012 | C15: JUEGO DE OLLAS Di'ROCCA NEGRO 10 PIEZAS ALTA GAMA OF25-10PCS | D15: =IFERROR((VLOOKUP(B15, Roccia!$B$2:$D997, 3, FALSE)*(1+Datos!$E$2)), "Revisar") -> 109.92 | E15: =IFERROR(D15*Datos!$B$3, "Revisar") -> 164.88 | F15: =IFERROR(E15*Datos!$B$1, "Revisar") -> 95225.801 | G15: =IFERROR((VLOOKUP(B15, Roccia!$B$2:$D997, 3, FALSE) /(1-Datos!$E$1)), "Revisar") -> 130.85714 | H15: =IFERROR(G15*Datos!$B$3, "Revisar") -> 196.28571 | I15: =IFERROR(H15-E15, "Revisar") -> 31.405714
A16: ARTÍCULOS DE COCINA | B16: K013 | C16: JUEGO DE OLLAS Di'ROCCA BLANCO 10 PIEZAS ALTA GAMA OF26-10PCS | D16: =IFERROR((VLOOKUP(B16, Roccia!$B$2:$D997, 3, FALSE)*(1+Datos!$E$2)), "Revisar") -> 109.92 | E16: =IFERROR(D16*Datos!$B$3, "Revisar") -> 164.88 | F16: =IFERROR(E16*Datos!$B$1, "Revisar") -> 95225.801 | G16: =IFERROR((VLOOKUP(B16, Roccia!$B$2:$D997, 3, FALSE) /(1-Datos!$E$1)), "Revisar") -> 130.85714 | H16: =IFERROR(G16*Datos!$B$3, "Revisar") -> 196.28571 | I16: =IFERROR(H16-E16, "Revisar") -> 31.405714
A17: ARTICULOS PARA PISCINAS | B17: B029L | C17: LAMPARA LED PARA PISCINA 29.2*7CM CON BORDE 12W/12V YC292-A | D17: =IFERROR((VLOOKUP(B17, Roccia!$B$2:$D997, 3, FALSE)*(1+Datos!$E$2)), "Revisar") -> 48.612 | E17: =IFERROR(D17*Datos!$B$3, "Revisar") -> 72.918 | F17: =IFERROR(E17*Datos!$B$1, "Revisar") -> 42113.507 | G17: =IFERROR((VLOOKUP(B17, Roccia!$B$2:$D997, 3, FALSE) /(1-Datos!$E$1)), "Revisar") -> 57.871429 | H17: =IFERROR(G17*Datos!$B$3, "Revisar") -> 86.807143 | I17: =IFERROR(H17-E17, "Revisar") -> 13.889143
A18: ARTICULOS PARA PISCINAS | B18: B030L | C18: LAMPARA LED PARA PISCINA 29.5*7CM BORDE INFINITO 12W/12V YC295-2A | D18: =IFERROR((VLOOKUP(B18, Roccia!$B$2:$D997, 3, FALSE)*(1+Datos!$E$2)), "Revisar") -> 52.404 | E18: =IFERROR(D18*Datos!$B$3, "Revisar") -> 78.606 | F18: =IFERROR(E18*Datos!$B$1, "Revisar") -> 45398.589 | G18: =IFERROR((VLOOKUP(B18, Roccia!$B$2:$D997, 3, FALSE) /(1-Datos!$E$1)), "Revisar") -> 62.385714 | H18: =IFERROR(G18*Datos!$B$3, "Revisar") -> 93.578571 | I18: =IFERROR(H18-E18, "Revisar") -> 14.972571
A19: ARTICULOS PARA PISCINAS | B19: B031L | C19: LAMPARA LED PARA PISCINA 23*4.8CM 12W/12V YC230-2A | D19: =IFERROR((VLOOKUP(B19, Roccia!$B$2:$D997, 3, FALSE)*(1+Datos!$E$2)), "Revisar") -> 48.576 | E19: =IFERROR(D19*Datos!$B$3, "Revisar") -> 72.864 | F19: =IFERROR(E19*Datos!$B$1, "Revisar") -> 42082.319 | G19: =IFERROR((VLOOKUP(B19, Roccia!$B$2:$D997, 3, FALSE) /(1-Datos!$E$1)), "Revisar") -> 57.828571 | H19: =IFERROR(G19*Datos!$B$3, "Revisar") -> 86.742857 | I19: =IFERROR(H19-E19, "Revisar") -> 13.878857
A20: ARTICULOS PARA PISCINAS | B20: B032L | C20: LAMPARA LED PARA PISCINA 23*4.8CM 12W/12V YC230-SW | D20: =IFERROR((VLOOKUP(B20, Roccia!$B$2:$D997, 3, FALSE)*(1+Datos!$E$2)), "Revisar") -> 48.612 | E20: =IFERROR(D20*Datos!$B$3, "Revisar") -> 72.918 | F20: =IFERROR(E20*Datos!$B$1, "Revisar") -> 42113.507 | G20: =IFERROR((VLOOKUP(B20, Roccia!$B$2:$D997, 3, FALSE) /(1-Datos!$E$1)), "Revisar") -> 57.871429 | H20: =IFERROR(G20*Datos!$B$3, "Revisar") -> 86.807143 | I20: =IFERROR(H20-E20, "Revisar") -> 13.889143
A21: ARTICULOS PARA PISCINAS | B21: B033L | C21: LAMPARA LED PARA PISCINA 30*7CM 18W/12V YC300-SW | D21: =IFERROR((VLOOKUP(B21, Roccia!$B$2:$D997, 3, FALSE)*(1+Datos!$E$2)), "Revisar") -> 70.224 | E21: =IFERROR(D21*Datos!$B$3, "Revisar") -> 105.336 | F21: =IFERROR(E21*Datos!$B$1, "Revisar") -> 60836.396 | G21: =IFERROR((VLOOKUP(B21, Roccia!$B$2:$D997, 3, FALSE) /(1-Datos!$E$1)), "Revisar") -> 83.6 | H21: =IFERROR(G21*Datos!$B$3, "Revisar") -> 125.4 | I21: =IFERROR(H21-E21, "Revisar") -> 20.064
A22: ARTICULOS PARA PISCINAS | B22: B034L | C22: ASPIRADORA DE PISCINAS RECARGABLE 2000MAH 40W RPC403 MARCA ROCCIA | D22: =IFERROR((VLOOKUP(B22, Roccia!$B$2:$D997, 3, FALSE)*(1+Datos!$E$2)), "Revisar") -> 107.46 | E22: =IFERROR(D22*Datos!$B$3, "Revisar") -> 161.19 | F22: =IFERROR(E22*Datos!$B$1, "Revisar") -> 93094.656 | G22: =IFERROR((VLOOKUP(B22, Roccia!$B$2:$D997, 3, FALSE) /(1-Datos!$E$1)), "Revisar") -> 127.92857 | H22: =IFERROR(G22*Datos!$B$3, "Revisar") -> 191.89286 | I22: =IFERROR(H22-E22, "Revisar") -> 30.702857
A23: ARTICULOS PARA PISCINAS | B23: B035L | C23: CLORIFICADOR SALINO INTELIGENTE 25g/h PARA PISCINAS LC250A | D23: =IFERROR((VLOOKUP(B23, Roccia!$B$2:$D997, 3, FALSE)*(1+Datos!$E$2)), "Revisar") -> 464.16 | E23: =IFERROR(D23*Datos!$B$3, "Revisar") -> 696.24 | F23: =IFERROR(E23*Datos!$B$1, "Revisar") -> 402110.7 | G23: =IFERROR((VLOOKUP(B23, Roccia!$B$2:$D997, 3, FALSE) /(1-Datos!$E$1)), "Revisar") -> 552.57143 | H23: =IFERROR(G23*Datos!$B$3, "Revisar") -> 828.85714 | I23: =IFERROR(H23-E23, "Revisar") -> 132.61714
A24: ARTICULOS PARA PISCINAS | B24: B036L | C24: CLORIFICADOR SALINO INTELIGENTE 30g/h PARA PISCINAS LC300A | D24: =IFERROR((VLOOKUP(B24, Roccia!$B$2:$D997, 3, FALSE)*(1+Datos!$E$2)), "Revisar") -> 525.396 | E24: =IFERROR(D24*Datos!$B$3, "Revisar") -> 788.094 | F24: =IFERROR(E24*Datos!$B$1, "Revisar") -> 455160.62 | G24: =IFERROR((VLOOKUP(B24, Roccia!$B$2:$D997, 3, FALSE) /(1-Datos!$E$1)), "Revisar") -> 625.47143 | H24: =IFERROR(G24*Datos!$B$3, "Revisar") -> 938.20714 | I24: =IFERROR(H24-E24, "Revisar") -> 150.11314
A25: ARTICULOS PARA PISCINAS | B25: B037L | C25: CLORIFICADOR SALINO INTELIGENTE 40g/h PARA PISCINAS LC400A | D25: =IFERROR((VLOOKUP(B25, Roccia!$B$2:$D997, 3, FALSE)*(1+Datos!$E$2)), "Revisar") -> 671.412 | E25: =IFERROR(D25*Datos!$B$3, "Revisar") -> 1007.118 | F25: =IFERROR(E25*Datos!$B$1, "Revisar") -> 581657.07 | G25: =IFERROR((VLOOKUP(B25, Roccia!$B$2:$D997, 3, FALSE) /(1-Datos!$E$1)), "Revisar") -> 799.3 | H25: =IFERROR(G25*Datos!$B$3, "Revisar") -> 1198.95 | I25: =IFERROR(H25-E25, "Revisar") -> 191.832
A26: ARTICULOS PARA PISCINAS | B26: B038L | C26: CLORIFICADOR SALINO INTELIGENTE 50g/h PARA PISCINAS LC500A | D26: =IFERROR((VLOOKUP(B26, Roccia!$B$2:$D997, 3, FALSE)*(1+Datos!$E$2)), "Revisar") -> 815.088 | E26: =IFERROR(D26*Datos!$B$3, "Revisar") -> 1222.632 | F26: =IFERROR(E26*Datos!$B$1, "Revisar") -> 706126.34 | G26: =IFERROR((VLOOKUP(B26, Roccia!$B$2:$D997, 3, FALSE) /(1-Datos!$E$1)), "Revisar") -> 970.34286 | H26: =IFERROR(G26*Datos!$B$3, "Revisar") -> 1455.5143 | I26: =IFERROR(H26-E26, "Revisar") -> 232.88229
A27: BALANZAS | B27: P001 | C27: BALANZA DE 40 KG | D27: =IFERROR((VLOOKUP(B27, Roccia!$B$2:$D997, 3, FALSE)*(1+Datos!$E$2)), "Revisar") -> 31.2 | E27: =IFERROR(D27*Datos!$B$3, "Revisar") -> 46.8 | F27: =IFERROR(E27*Datos!$B$1, "Revisar") -> 27029.157 | G27: =IFERROR((VLOOKUP(B27, Roccia!$B$2:$D997, 3, FALSE) /(1-Datos!$E$1)), "Revisar") -> 37.142857 | H27: =IFERROR(G27*Datos!$B$3, "Revisar") -> 55.714286 | I27: =IFERROR(H27-E27, "Revisar") -> 8.9142857
A28: BALANZAS | B28: P003 | C28: BALANZA DE 7 KG | D28: =IFERROR((VLOOKUP(B28, Roccia!$B$2:$D997, 3, FALSE)*(1+Datos!$E$2)), "Revisar") -> 4.2 | E28: =IFERROR(D28*Datos!$B$3, "Revisar") -> 6.3 | F28: =IFERROR(E28*Datos!$B$1, "Revisar") -> 3638.5404 | G28: =IFERROR((VLOOKUP(B28, Roccia!$B$2:$D997, 3, FALSE) /(1-Datos!$E$1)), "Revisar") -> 5 | H28: =IFERROR(G28*Datos!$B$3, "Revisar") -> 7.5 | I28: =IFERROR(H28-E28, "Revisar") -> 1.2
A29: BALANZAS | B29: P011 | C29: ROMANA DE 200 KG | D29: =IFERROR((VLOOKUP(B29, Roccia!$B$2:$D997, 3, FALSE)*(1+Datos!$E$2)), "Revisar") -> 50.4 | E29: =IFERROR(D29*Datos!$B$3, "Revisar") -> 75.6 | F29: =IFERROR(E29*Datos!$B$1, "Revisar") -> 43662.485 | G29: =IFERROR((VLOOKUP(B29, Roccia!$B$2:$D997, 3, FALSE) /(1-Datos!$E$1)), "Revisar") -> 60 | H29: =IFERROR(G29*Datos!$B$3, "Revisar") -> 90 | I29: =IFERROR(H29-E29, "Revisar") -> 14.4
A30: BALANZAS | B30: P012 | C30: ROMANA DE 350 KG | D30: =IFERROR((VLOOKUP(B30, Roccia!$B$2:$D997, 3, FALSE)*(1+Datos!$E$2)), "Revisar") -> 72 | E30: =IFERROR(D30*Datos!$B$3, "Revisar") -> 108 | F30: =IFERROR(E30*Datos!$B$1, "Revisar") -> 62374.979 | G30: =IFERROR((VLOOKUP(B30, Roccia!$B$2:$D997, 3, FALSE) /(1-Datos!$E$1)), "Revisar") -> 85.714286 | H30: =IFERROR(G30*Datos!$B$3, "Revisar") -> 128.57143 | I30: =IFERROR(H30-E30, "Revisar") -> 20.571429
A31: BALANZAS | B31: P013 | C31: ROMANA DE 700 KG | D31: =IFERROR((VLOOKUP(B31, Roccia!$B$2:$D997, 3, FALSE)*(1+Datos!$E$2)), "Revisar") -> 120 | E31: =IFERROR(D31*Datos!$B$3, "Revisar") -> 180 | F31: =IFERROR(E31*Datos!$B$1, "Revisar") -> 103958.3 | G31: =IFERROR((VLOOKUP(B31, Roccia!$B$2:$D997, 3, FALSE) /(1-Datos!$E$1)), "Revisar") -> 142.85714 | H31: =IFERROR(G31*Datos!$B$3, "Revisar") -> 214.28571 | I31: =IFERROR(H31-E31, "Revisar") -> 34.285714
A32: BALANZAS | B32: P014 | C32: ROMANA WIFI 300 KG | D32: =IFERROR((VLOOKUP(B32, Roccia!$B$2:$D997, 3, FALSE)*(1+Datos!$E$2)), "Revisar") -> 87.78 | E32: =IFERROR(D32*Datos!$B$3, "Revisar") -> 131.67 | F32: =IFERROR(E32*Datos!$B$1, "Revisar") -> 76045.495 | G32: =IFERROR((VLOOKUP(B32, Roccia!$B$2:$D997, 3, FALSE) /(1-Datos!$E$1)), "Revisar") -> 104.5 | H32: =IFERROR(G32*Datos!$B$3, "Revisar") -> 156.75 | I32: =IFERROR(H32-E32, "Revisar") -> 25.08
A33: BALANZAS | B33: P016 | C33: ROMANA DE 3T 1*1 | D33: =IFERROR((VLOOKUP(B33, Roccia!$B$2:$D997, 3, FALSE)*(1+Datos!$E$2)), "Revisar") -> 448.476 | E33: =IFERROR(D33*Datos!$B$3, "Revisar") -> 672.714 | F33: =IFERROR(E33*Datos!$B$1, "Revisar") -> 388523.35 | G33: =IFERROR((VLOOKUP(B33, Roccia!$B$2:$D997, 3, FALSE) /(1-Datos!$E$1)), "Revisar") -> 533.9 | H33: =IFERROR(G33*Datos!$B$3, "Revisar") -> 800.85 | I33: =IFERROR(H33-E33, "Revisar") -> 128.136
A34: BALANZAS | B34: P017 | C34: ROMANA DE 3T 1,20*1,20 | D34: =IFERROR((VLOOKUP(B34, Roccia!$B$2:$D997, 3, FALSE)*(1+Datos!$E$2)), "Revisar") -> 475.836 | E34: =IFERROR(D34*Datos!$B$3, "Revisar") -> 713.754 | F34: =IFERROR(E34*Datos!$B$1, "Revisar") -> 412225.84 | G34: =IFERROR((VLOOKUP(B34, Roccia!$B$2:$D997, 3, FALSE) /(1-Datos!$E$1)), "Revisar") -> 566.47143 | H34: =IFERROR(G34*Datos!$B$3, "Revisar") -> 849.70714 | I34: =IFERROR(H34-E34, "Revisar") -> 135.95314
A35: BALANZAS | B35: P018 | C35: ROMANA DE 3T 1,50*2 | D35: =IFERROR((VLOOKUP(B35, Roccia!$B$2:$D997, 3, FALSE)*(1+Datos!$E$2)), "Revisar") -> 783.624 | E35: =IFERROR(D35*Datos!$B$3, "Revisar") -> 1175.436 | F35: =IFERROR(E35*Datos!$B$1, "Revisar") -> 678868.48 | G35: =IFERROR((VLOOKUP(B35, Roccia!$B$2:$D997, 3, FALSE) /(1-Datos!$E$1)), "Revisar") -> 932.88571 | H35: =IFERROR(G35*Datos!$B$3, "Revisar") -> 1399.3286 | I35: =IFERROR(H35-E35, "Revisar") -> 223.89257
A36: BALANZAS | B36: P019 | C36: BALANZA DE GANCHO RECARGABLE 50KG GOOD QUALITY YZ-S03 | D36: =IFERROR((VLOOKUP(B36, Roccia!$B$2:$D997, 3, FALSE)*(1+Datos!$E$2)), "Revisar") -> 8.4 | E36: =IFERROR(D36*Datos!$B$3, "Revisar") -> 12.6 | F36: =IFERROR(E36*Datos!$B$1, "Revisar") -> 7277.0809 | G36: =IFERROR((VLOOKUP(B36, Roccia!$B$2:$D997, 3, FALSE) /(1-Datos!$E$1)), "Revisar") -> 10 | H36: =IFERROR(G36*Datos!$B$3, "Revisar") -> 15 | I36: =IFERROR(H36-E36, "Revisar") -> 2.4
A37: BALANZAS | B37: P020 | C37: BALANZA DE COCINA 3KG GOOD QUALITY X1-C3B | D37: =IFERROR((VLOOKUP(B37, Roccia!$B$2:$D997, 3, FALSE)*(1+Datos!$E$2)), "Revisar") -> 17.7 | E37: =IFERROR(D37*Datos!$B$3, "Revisar") -> 26.55 | F37: =IFERROR(E37*Datos!$B$1, "Revisar") -> 15333.849 | G37: =IFERROR((VLOOKUP(B37, Roccia!$B$2:$D997, 3, FALSE) /(1-Datos!$E$1)), "Revisar") -> 21.071429 | H37: =IFERROR(G37*Datos!$B$3, "Revisar") -> 31.607143 | I37: =IFERROR(H37-E37, "Revisar") -> 5.0571429
A38: BALANZAS | B38: P021 | C38: BALANZA DE MOSTRADOR CAP 30KG DE ALTA PRECISION 905 | D38: =IFERROR((VLOOKUP(B38, Roccia!$B$2:$D997, 3, FALSE)*(1+Datos!$E$2)), "Revisar") -> 40.968 | E38: =IFERROR(D38*Datos!$B$3, "Revisar") -> 61.452 | F38: =IFERROR(E38*Datos!$B$1, "Revisar") -> 35491.363 | G38: =IFERROR((VLOOKUP(B38, Roccia!$B$2:$D997, 3, FALSE) /(1-Datos!$E$1)), "Revisar") -> 48.771429 | H38: =IFERROR(G38*Datos!$B$3, "Revisar") -> 73.157143 | I38: =IFERROR(H38-E38, "Revisar") -> 11.705143
A39: BALANZAS | B39: P021S | C39: BALANZA DE MOSTRADOR CAP 30KG DE ALTA PRECISION 905 CON SENCAMER | D39: =IFERROR((VLOOKUP(B39, Roccia!$B$2:$D997, 3, FALSE)*(1+Datos!$E$2)), "Revisar") -> 72 | E39: =IFERROR(D39*Datos!$B$3, "Revisar") -> 108 | F39: =IFERROR(E39*Datos!$B$1, "Revisar") -> 62374.979 | G39: =IFERROR((VLOOKUP(B39, Roccia!$B$2:$D997, 3, FALSE) /(1-Datos!$E$1)), "Revisar") -> 85.714286 | H39: =IFERROR(G39*Datos!$B$3, "Revisar") -> 128.57143 | I39: =IFERROR(H39-E39, "Revisar") -> 20.571429
A40: BALANZAS | B40: P022 | C40: BALANZA DE MOSTRADOR CON SU VISOR CAP 30KG DE ALTA PRECISION 905ARM | D40: =IFERROR((VLOOKUP(B40, Roccia!$B$2:$D997, 3, FALSE)*(1+Datos!$E$2)), "Revisar") -> 54.216 | E40: =IFERROR(D40*Datos!$B$3, "Revisar") -> 81.324 | F40: =IFERROR(E40*Datos!$B$1, "Revisar") -> 46968.359 | G40: =IFERROR((VLOOKUP(B40, Roccia!$B$2:$D997, 3, FALSE) /(1-Datos!$E$1)), "Revisar") -> 64.542857 | H40: =IFERROR(G40*Datos!$B$3, "Revisar") -> 96.814286 | I40: =IFERROR(H40-E40, "Revisar") -> 15.490286
...

Sheet Datos
A1: BCV | B1: 577.5461 | C1: 46184.481 | D1: Ganancia | E1: 0.3
A2: Binance | B2: 866.31 | D2: Ganancia - Sin Ajuste | E2: 0.2
A3: % Venta | B3: =ROUNDUP(((B2-B1)/B1)+1,2) -> 1.5

Sheet Roccia
A1: TIPO | B1: CODIGO | C1: PRODUCTO | D1: COSTO
A2: ARTÍCULOS DE COCINA | B2: K001 | C2: JUEGO DE OLLAS DE GRANITO ANTIADHERENTE 12 PIEZAS DE LUJO NERO ROCCIA | D2: 110.31
A3: ARTÍCULOS DE COCINA | B3: K003 | C3: JUEGO DE SARTENES 3 PIEZAS NERO MARCA ROCCIA | D3: 36.14
A4: ARTÍCULOS DE COCINA | B4: K004 | C4: WOK DE 28CM CON TAPA DE CRISTAL MARCA ROCCIA | D4: 21.57
A5: ARTÍCULOS DE COCINA | B5: K005 | C5: JUEGO DE OLLAS GRANITE 14 PIEZAS MARCA ROCCIA | D5: 87.55
A6: ARTÍCULOS DE COCINA | B6: K006 | C6: BUDARE 28CM CUADRADO NERO MARCA ROCCIA | D6: 10.99
A7: ARTÍCULOS DE COCINA | B7: K007G | C7: JUEGO DE UTENSILIOS DE COCINA 12 PIEZAS SILICONE ANTIRAYA GRIS | D7: 11
A8: ARTÍCULOS DE COCINA | B8: K007V | C8: JUEGO DE UTENSILIOS DE COCINA 12 PIEZAS SILICONE ANTIRAYA VERDE | D8: 11
A9: ARTÍCULOS DE COCINA | B9: K007N | C9: JUEGO DE UTENSILIOS DE COCINA 12 PIEZAS SILICONE ANTIRAYA NEGRO | D9: 11
A10: ARTÍCULOS DE COCINA | B10: K007B | C10: JUEGO DE UTENSILIOS DE COCINA 12 PIEZAS SILICONE ANTIRAYA BEIGE | D10: 11
A11: ARTÍCULOS DE COCINA | B11: K008 | C11: JUEGO DE 7 CUCHILLOS DE ALTA GAMA MARCA ROCCIA | D11: 30.91
A12: ARTÍCULOS DE COCINA | B12: K009 | C12: JUEGO DE 5 CUCHILLOS DE ACERO INOXIDABLE | D12: 15
A13: ARTÍCULOS DE COCINA | B13: K010 | C13: SET DE OLLAS DILUSSO 8 PIEZAS DE ACERO INOXIDABLE MARCA ROCCIA | D13: 100.77
... A397: VENTILADORES | B397: F027 | C397: VENTILADOR DE PARED 16¨ METAL PLASTICO CON CONTROL MARCA ROCCIA | D397: 23.61

Sheet Pagos
A1: Semana | B1: Fecha | C1: Monto | D1: Corresponde | E1: Referencia
A2: 12/04 al 18/04 | B2: 13/04/2026 | C2: 15000 | D2: 25 | E2: 61032341240
A3: 19/04 al 25/04 | B3: --- | C3: --- | D3: --- | E3: ---
A4: 26/04 al 02/05 | B4: 27/04/2026 | C4: 15000 | D4: 25 | E4: 61175275979
A5: 03/05 al 09/05 | B5: 46178 | C5: 15500 | D5: 25 | E5: 61263587001
A6: 10/05 al 16/05 | B6: 19/05/2026 | C6: 19500 | D6: 30
A7: 17/05 al 23/05 | B7: 26/05/2026 | C7: 21000 | D7: 30
A8: 24/05 al 30/05
A9: 31/05 al 06/06
